<?xml version="1.0" ?>
<!-- =================================================================================== -->
<!-- |    This document was autogenerated by xacro from /opt/ros/kinetic/share/moveit_resources/panda_description/urdf/panda.urdf | -->
<!-- |    EDITING THIS FILE BY HAND IS NOT RECOMMENDED                                 | -->
<!-- =================================================================================== -->
<robot name="panda" xmlns:xacro="http://www.ros.org/wiki/xacro">

    <xacro:include filename="panda.urdf.xacro" />
    
    <link name="world"></link>
    
    <joint name="world_to_base_joint" type="fixed">
    	<origin xyz="0.5 0.375 0.25" rpy="0 0 0"/>
    	<parent link="world"/>
    	<child link="base_link"/>
    </joint>
    
    <link name="base_link">
    	<visual>
          <geometry>
            <box size="1.0 0.75 0.5"/>
          </geometry>
        </visual>
        <inertial>
            <origin rpy="0 0.0 0" xyz="0.0 0.0 0.0"/>
            <mass value="100.0"/>
            <inertia ixx="10" ixy="0.0" ixz="0.0" iyy="10" iyz="0.0" izz="10"/>
        </inertial>
    </link>
    
    <joint name="box_to_second_box_joint" type="fixed">
        <origin xyz="-0.625 0 0.125" rpy="0 0 0"/>
        <parent link="base_link"/>
        <child link="second_box_link"/>        
    </joint>
    
    <link name="second_box_link">
    	<visual>
          <geometry>
            <box size="0.25 0.1 0.1"/>
          </geometry>
        </visual>
        <inertial>
            <origin rpy="0 0.0 0" xyz="0.0 0.0 0.0"/>
            <mass value="1.0"/>
            <inertia ixx="1" ixy="0.0" ixz="0.0" iyy="1" iyz="0.0" izz="1"/>
        </inertial>
    </link>
    
    <joint name="box_to_tyre_joint" type="fixed">
        <origin xyz="-0.425 0 0" rpy="1.57 0 0"/>
        <parent link="second_box_link"/>
        <child link="tyre_link"/>        
    </joint>
    
    <link name="tyre_link">
    	<visual>
          <geometry>
            <cylinder radius="0.3" length="0.3" />
          </geometry>
        </visual>
        <inertial>
            <origin rpy="0 0 0" xyz="0.0 0.0 0.0"/>
            <mass value="1.0"/>
            <inertia ixx="1" ixy="0.0" ixz="0.0" iyy="1" iyz="0.0" izz="1"/>
        </inertial>
    </link>

    
    <joint name="base_joint" type="fixed">
        <origin xyz="-0.25 0.0 0.25" rpy="0 0 0"/>
        <parent link="base_link"/>
        <child link="panda_link0"/>        
    </joint>
    
    <link name="panda_link0">
        <visual>
            <geometry>
                <mesh filename="$(find panda_data)/meshes/visual/link0.dae" />
            </geometry>
        </visual>
        <collision>
            <geometry>
                <mesh filename="$(find panda_data)/meshes/collision/link0.stl" />
            </geometry>
        </collision>
        <inertial>
            <origin rpy="0 0 0" xyz="-0.041018 -0.00014 0.049974"/>
            <mass value="0.629769"/>
            <inertia ixx="0.00315" ixy="8.2904e-07" ixz="0.00015" iyy="0.00388" iyz="8.2299e-06" izz="0.004285"/>
        </inertial>
    </link>
    <link name="panda_link1">
        <visual>
            <geometry>
                <mesh filename="$(find panda_data)/meshes/visual/link1.dae" />
            </geometry>
        </visual>
        <collision>
            <geometry>
                <mesh filename="$(find panda_data)/meshes/collision/link1.stl" />
            </geometry>
        </collision>
        <inertial>
            <origin rpy="0 0 0" xyz="0.003875 0.002081 -0.04762"/>
            <mass value="4.970684"/>
            <inertia ixx="0.70337" ixy="-0.000139" ixz="0.006772" iyy="0.70661" iyz="0.019169" izz="0.009117"/>
        </inertial>
    </link>
    <joint name="panda_joint1" type="revolute">
        <safety_controller k_position="100.0" k_velocity="40.0" soft_lower_limit="-2.8973" soft_upper_limit="2.8973" />
        <origin rpy="0 0 0" xyz="0 0 0.333" />
        <parent link="panda_link0" />
        <child link="panda_link1" />
        <axis xyz="0 0 1" />
        <limit effort="87" lower="-2.9671" upper="2.9671" velocity="2.3925" />
        <dynamics D="1" K="7000" damping="1.0" friction="0.0" mu_coulomb="0" mu_viscous="16"/>
    </joint>
    <link name="panda_link2">
        <visual>
            <geometry>
                <mesh filename="$(find panda_data)/meshes/visual/link2.dae" />
            </geometry>
        </visual>
        <collision>
            <geometry>
                <mesh filename="$(find panda_data)/meshes/collision/link2.stl" />
            </geometry>
        </collision>
        <inertial>
            <origin rpy="0 0 0" xyz="-0.003141 -0.02872  0.003495"/>
            <mass value="0.646926"/>
            <inertia ixx="0.007962" ixy="-0.003925" ixz="0.010254" iyy="0.02811" iyz="0.000704" izz="0.025995"/>
        </inertial>
    </link>
    <joint name="panda_joint2" type="revolute">
        <safety_controller k_position="100.0" k_velocity="40.0" soft_lower_limit="-1.7628" soft_upper_limit="1.7628" />
        <origin rpy="-1.57079632679 0 0" xyz="0 0 0" />
        <parent link="panda_link1" />
        <child link="panda_link2" />
        <axis xyz="0 0 1" />
        <limit effort="87" lower="-1.8326" upper="1.8326" velocity="2.3925" />
        <dynamics D="1" K="7000" damping="1.0" friction="0.0" mu_coulomb="0" mu_viscous="16"/>
    </joint>
    <link name="panda_link3">
        <visual>
            <geometry>
                <mesh filename="$(find panda_data)/meshes/visual/link3.dae" />
            </geometry>
        </visual>
        <collision>
            <geometry>
                <mesh filename="$(find panda_data)/meshes/collision/link3.stl" />
            </geometry>
        </collision>
        <inertial>
            <origin rpy="0 0 0" xyz="2.7518e-02 3.9252e-02 -6.6502e-02"/>
            <mass value="3.228604"/>
            <inertia ixx="0.037242" ixy="-0.004761" ixz="-0.011396" iyy="0.036155" iyz="-0.012805" izz="0.01083"/>
        </inertial>
    </link>
    <joint name="panda_joint3" type="revolute">
        <safety_controller k_position="100.0" k_velocity="40.0" soft_lower_limit="-2.8973" soft_upper_limit="2.8973" />
        <origin rpy="1.57079632679 0 0" xyz="0 -0.316 0" />
        <parent link="panda_link2" />
        <child link="panda_link3" />
        <axis xyz="0 0 1" />
        <limit effort="87" lower="-2.9671" upper="2.9671" velocity="2.3925" />
        <dynamics D="1" K="7000" damping="1.0" friction="0.0" mu_coulomb="0" mu_viscous="16"/>
    </joint>
    <link name="panda_link4">
        <visual>
            <geometry>
                <mesh filename="$(find panda_data)/meshes/visual/link4.dae" />
            </geometry>
        </visual>
        <collision>
            <geometry>
                <mesh filename="$(find panda_data)/meshes/collision/link4.stl" />
            </geometry>
        </collision>
        <inertial>
            <origin rpy="0 0 0" xyz="-5.317e-02 1.04419e-01 2.7454e-02"/>
            <mass value="3.587895"/>
            <inertia ixx="0.025853" ixy="0.007796" ixz="-0.001332" iyy="0.019552" iyz="0.008641" izz="0.028323"/>
        </inertial>
    </link>
    <joint name="panda_joint4" type="revolute">
        <safety_controller k_position="100.0" k_velocity="40.0" soft_lower_limit="-3.0718" soft_upper_limit="0.0175" />
        <origin rpy="1.57079632679 0 0" xyz="0.0825 0 0" />
        <parent link="panda_link3" />
        <child link="panda_link4" />
        <axis xyz="0 0 1" />
        <limit effort="87" lower="-3.1416" upper="0.0873" velocity="2.3925" />
        <dynamics D="1" K="7000" damping="1.0" friction="0.0" mu_coulomb="0" mu_viscous="16"/>
    </joint>
    <link name="panda_link5">
        <visual>
            <geometry>
                <mesh filename="$(find panda_data)/meshes/visual/link5.dae" />
            </geometry>
        </visual>
        <collision>
            <geometry>
                <mesh filename="$(find panda_data)/meshes/collision/link5.stl" />
            </geometry>
        </collision>
        <inertial>
            <origin rpy="0 0 0" xyz="-1.1953e-02 4.1065e-02 -3.8437e-02"/>
            <mass value="1.225946"/>
            <inertia ixx="0.035549" ixy="-0.002117" ixz="-0.004037" iyy="0.029474" iyz="0.000229" izz="0.008627"/>
        </inertial>
    </link>
    <joint name="panda_joint5" type="revolute">
        <safety_controller k_position="100.0" k_velocity="40.0" soft_lower_limit="-2.8973" soft_upper_limit="2.8973" />
        <origin rpy="-1.57079632679 0 0" xyz="-0.0825 0.384 0" />
        <parent link="panda_link4" />
        <child link="panda_link5" />
        <axis xyz="0 0 1" />
        <limit effort="12" lower="-2.9671" upper="2.9671" velocity="2.8710" />
        <dynamics D="1" K="7000" damping="1.0" friction="0.0" mu_coulomb="0" mu_viscous="16"/>
    </joint>
    <link name="panda_link6">
        <visual>
            <geometry>
                <mesh filename="$(find panda_data)/meshes/visual/link6.dae" />
            </geometry>
        </visual>
        <collision>
            <geometry>
                <mesh filename="$(find panda_data)/meshes/collision/link6.stl" />
            </geometry>
        </collision>
        <inertial>
            <origin rpy="0 0 0" xyz="6.0149e-02 -1.4117e-02 -1.0517e-02"/>
            <mass value="1.666555"/>
            <inertia ixx="0.001964" ixy="0.000109" ixz="-0.001158" iyy="0.004354" iyz="0.000341" izz="0.005433"/>
        </inertial>
    </link>
    <joint name="panda_joint6" type="revolute">
        <safety_controller k_position="100.0" k_velocity="40.0" soft_lower_limit="-0.0175" soft_upper_limit="3.7525" />
        <origin rpy="1.57079632679 0 0" xyz="0 0 0" />
        <parent link="panda_link5" />
        <child link="panda_link6" />
        <axis xyz="0 0 1" />
        <limit effort="12" lower="-0.0873" upper="3.8223" velocity="2.8710" />
        <dynamics D="1" K="7000" damping="1.0" friction="0.0" mu_coulomb="0" mu_viscous="16"/>
    </joint>
    <link name="panda_link7">
        <visual>
            <geometry>
                <mesh filename="$(find panda_data)/meshes/visual/link7.dae" />
            </geometry>
        </visual>
        <collision>
            <geometry>
                <mesh filename="$(find panda_data)/meshes/collision/link7.stl" />
            </geometry>
        </collision>
        <inertial>
            <origin rpy="0 0 0" xyz="1.0517e-02 -4.252e-03 6.1597e-02"/>
            <mass value="0.735522"/>
            <inertia ixx="0.012516" ixy="-0.000428" ixz="-0.001196" iyy="0.010027" iyz="-0.000741" izz="0.004815"/>
        </inertial>
    </link>
    <joint name="panda_joint7" type="revolute">
        <safety_controller k_position="100.0" k_velocity="40.0" soft_lower_limit="-2.8973" soft_upper_limit="2.8973" />
        <origin rpy="1.57079632679 0 0" xyz="0.088 0 0" />
        <parent link="panda_link6" />
        <child link="panda_link7" />
        <axis xyz="0 0 1" />
        <limit effort="12" lower="-2.9671" upper="2.9671" velocity="2.8710" />
        <dynamics D="1" K="7000" damping="1.0" friction="0.0" mu_coulomb="0" mu_viscous="16"/>
    </joint>
    <link name="panda_link8" />
    <joint name="panda_joint8" type="fixed">
        <origin rpy="0 0 0" xyz="0 0 0.107" />
        <parent link="panda_link7" />
        <child link="panda_link8" />
        <axis xyz="0 0 0" />
    </joint>
    <joint name="panda_hand_joint" type="fixed">
        <parent link="panda_link8" />
        <child link="panda_hand" />
        <origin rpy="0 0 -0.785398163397" xyz="0 0 0" />
    </joint>
    <link name="panda_hand">
        <visual>
            <geometry>
                <mesh filename="$(find panda_data)/meshes/visual/hand.dae" />
            </geometry>
        </visual>
        <collision>
            <geometry>
                <mesh filename="$(find panda_data)/meshes/collision/hand.stl" />
            </geometry>
        </collision>
    </link>
    <link name="panda_leftfinger">
        <visual>
            <geometry>
                <mesh filename="$(find panda_data)/meshes/visual/finger.dae" />
            </geometry>
        </visual>
        <collision>
            <geometry>
                <mesh filename="$(find panda_data)/meshes/collision/finger.stl" />
            </geometry>
        </collision>
    </link>
    <link name="panda_rightfinger">
        <visual>
            <origin rpy="0 0 3.14159265359" xyz="0 0 0" />
            <geometry>
                <mesh filename="$(find panda_data)/meshes/visual/finger.dae" />
            </geometry>
        </visual>
        <collision>
            <origin rpy="0 0 3.14159265359" xyz="0 0 0" />
            <geometry>
                <mesh filename="$(find panda_data)/meshes/collision/finger.stl" />
            </geometry>
        </collision>
    </link>
    <joint name="panda_finger_joint1" type="prismatic">
        <parent link="panda_hand" />
        <child link="panda_leftfinger" />
        <origin rpy="0 0 0" xyz="0 0 0.0584" />
        <axis xyz="0 1 0" />
        <limit effort="20" lower="0.0" upper="0.04" velocity="0.2" />
        <dynamics damping="0.3"/>
    </joint>
    <joint name="panda_finger_joint2" type="prismatic">
        <parent link="panda_hand" />
        <child link="panda_rightfinger" />
        <origin rpy="0 0 0" xyz="0 0 0.0584" />
        <axis xyz="0 -1 0" />
        <limit effort="20" lower="0.0" upper="0.04" velocity="0.2" />
        <mimic joint="panda_finger_joint1" />
        <dynamics damping="0.3"/>
    </joint>
    
    <gazebo reference="panda_link0">
    <material>Gazebo/White</material>
     </gazebo>
    
    <gazebo reference="panda_link1">
    <material>Gazebo/White</material>
     </gazebo>
     
    <gazebo reference="panda_link2">
    <material>Gazebo/White</material>
     </gazebo> 
     
    <gazebo reference="panda_link3">
    <material>Gazebo/White</material>
     </gazebo> 
     
    <gazebo reference="panda_link4">
    <material>Gazebo/White</material>
     </gazebo> 
     
    <gazebo reference="panda_link5">
    <material>Gazebo/White</material>
     </gazebo> 
     
    <gazebo reference="panda_link6">
    <material>Gazebo/White</material>
     </gazebo> 
     
    <gazebo reference="panda_link7">
    <material>Gazebo/White</material>
     </gazebo>
     
     <!-- get joint states from ROS -->

    <gazebo>
        <plugin name="gazebo_ros_joint_state_publisher"
            filename="libgazebo_ros_joint_state_publisher.so">
            <update_rate>20</update_rate>
            <joint_name>panda_joint1</joint_name>
            <joint_name>panda_joint2</joint_name>
            <joint_name>panda_joint3</joint_name>
            <joint_name>panda_joint4</joint_name>
            <joint_name>panda_joint5</joint_name>
            <joint_name>panda_joint6</joint_name>
            <joint_name>panda_joint7</joint_name>
        </plugin>
    </gazebo>
    
    <!-- new version -->
    <gazebo>
        <plugin filename="libgazebo_ros2_control.so" name="gazebo_ros2_control">
            <parameters>$(find panda_workflow_test)/config/ros2_controllers.yaml</parameters>
        </plugin>
    </gazebo>
</robot>
